Workbook

Sheet SELECTION
A1: ID marqueur | B1: Evénement | C1: Année | D1: Genre | E1: Timing début | F1: Timing fin | G1: Lemme | H1: POS-TAG | I1: Type morpho-syntaxique | J1: Position du marqueur dans l'UCT | K1: Position de l'UCT dans le TDP | L1: Rôle de l'UCT dans la séquence | M1: Regard avant le marqueur | N1: Regard pendant le marqueur | O1: Regard après le marqueur | P1: Présence d'un geste? | Q1: Type de geste | R1: Direction | S1: Source | T1: Polarité
A2: 20001 | B2: DPU_UDC | C2: 2007 | D2: Débat public | E2: 804366 | F2: 804552 | G2: SEMBLER | H2: verbe | I2: construction attributive à verbe copule | J2: milieu | K2: milieu | L2: indéterminé | M2: allocutaire(s) | N2: allocutaire(s) | O2: allocutaire(s) | P2: non | R2: à l'intérieur | S2: ML | T2: positive
A3: 20002 | B3: DPU_REC | C3: 2007 | D3: Débat public | E3: 1352035 | F3: 1352284 | G3: PARAÎTRE | H3: verbe | I3: construction attributive à verbe copule | J3: début* | K3: milieu | L3: indéterminé | M3: allocutaire(s) | N3: autre | O3: autre | P3: oui | Q3: Meta.Aura | R3: à l'intérieur | S3: ML | T3: positive
A4: 20003 | B4: DPU_UDC | C4: 2007 | D4: Débat public | E4: 1888187 | F4: 1888333 | G4: PARAÎTRE | H4: verbe | I4: construction attributive à verbe copule | J4: milieu | K4: milieu | L4: indéterminé | M4: allocutaire(s) | N4: allocutaire(s) | O4: allocutaire(s) | P4: oui | Q4: Deictic.Addressee | R4: à l'intérieur | S4: ML | T4: positive
A5: 20004 | B5: DTV_SM1 | C5: 2007 | D5: Débat télévisé | E5: 340280 | F5: 341094 | G5: PARAÎTRE | H5: verbe | I5: construction attributive à verbe copule | J5: début* | K5: milieu | L5: indéterminé | M5: autre | N5: indéterminable | O5: autre | P5: impossible à déterminer | R5: portée<marqueur | S5: ML | T5: positive
A6: 20005 | B6: DTV_SM2 | C6: 2013 | D6: Débat télévisé | E6: 880398 | F6: 880572 | G6: PARAÎTRE | H6: verbe | I6: construction attributive à verbe copule | J6: milieu | K6: milieu | L6: indéterminé | M6: indéterminable | N6: indéterminable | O6: indéterminable | P6: impossible à déterminer | R6: à l'intérieur | S6: ML | T6: positive
A7: 20006 | B7: REU_BL1 | C7: 2017 | D7: Réunion professionnelle | E7: 2729947 | F7: 2730002 | G7: PARAÎTRE | H7: verbe | I7: construction attributive à verbe copule | J7: début* | K7: totalité | L7: indéterminé | M7: objet (symbolique) | N7: objet (symbolique) | O7: objet (symbolique) | P7: oui | Q7: Deictic.Object | R7: à l'intérieur | S7: ML | T7: positive
A8: 20007 | B8: DPU_MED | C8: 2008 | D8: Débat public | E8: 2878433 | F8: 2878820 | G8: AVOIR L'AIR | H8: locution verbale | I8: construction attributive à verbe copule | J8: début* | K8: milieu | L8: indéterminé | M8: allocutaire(s) | N8: allocutaire(s) | O8: allocutaire(s) | P8: non | R8: portée<marqueur | S8: ML | T8: positive
A9: 20008 | B9: DTV_DEM | C9: 2007 | D9: Débat télévisé | E9: 3199465 | F9: 3199624 | G9: AVOIR L'AIR | H9: locution verbale | I9: construction attributive à verbe copule | J9: milieu | K9: début | L9: initiatif | M9: indéterminable | N9: indéterminable | O9: indéterminable | P9: oui | Q9: Deictic.Indeterminable | R9: à l'intérieur | S9: ML | T9: positive
A10: 20009 | B10: DTV_VEH | C10: 2007 | D10: Débat télévisé | E10: 463064 | F10: 463380 | G10: AVOIR L'AIR | H10: locution verbale | I10: construction attributive à verbe copule | J10: fin* | K10: fin | L10: indéterminé | M10: indéterminable | N10: indéterminable | O10: indéterminable | P10: oui | Q10: Deictic.Indeterminable | R10: à l'intérieur | S10: ML | T10: positive
A11: 20010 | B11: DPU_BIE | C11: 2009 | D11: Débat public | E11: 2384187 | F11: 2385363 | G11: AVOIR L'IMPRESSION | H11: locution verbale | I11: prédicat verbal à complément | J11: milieu | K11: milieu | L11: initiatif | M11: allocutaire(s) | N11: allocutaire(s) | O11: allocutaire(s) | P11: oui | Q11: Deictic.Self | R11: marqueur>portée | S11: ML | T11: positive
A12: 20012 | B12: DTV_VEH | C12: 2007 | D12: Débat télévisé | E12: 3480664 | F12: 3481291 | G12: AVOIR L'IMPRESSION | H12: locution verbale | I12: prédicat verbal à complément | J12: début* | K12: fin | L12: initiatif | M12: indéterminable | N12: indéterminable | O12: indéterminable | P12: oui | Q12: Deictic.Addressee | R12: marqueur>portée | S12: ML | T12: neutre
A13: 20013 | B13: REU_AC1 | C13: 2017 | D13: Réunion professionnelle | E13: 1996191 | F13: 1996800 | G13: AVOIR L'IMPRESSION | H13: locution verbale | I13: prédicat verbal à complément | J13: milieu | K13: milieu | L13: indéterminé | M13: allocutaire(s) | N13: allocutaire(s) | O13: allocutaire(s) | P13: non | R13: marqueur>portée | S13: ML | T13: positive
A14: 20014 | B14: REU_BM3 | C14: 2017 | D14: Réunion professionnelle | E14: 3146178 | F14: 3146624 | G14: AVOIR L'IMPRESSION | H14: locution verbale | I14: prédicat verbal à complément | J14: milieu | K14: totalité | L14: indéterminé | M14: objet (symbolique) | N14: objet (symbolique) | O14: objet (symbolique) | P14: non | R14: marqueur>portée | S14: ML | T14: positive
A15: 20015 | B15: REU_CL1 | C15: 2017 | D15: Réunion professionnelle | E15: 2888539 | F15: 2888989 | G15: AVOIR L'IMPRESSION | H15: locution verbale | I15: prédicat verbal à complément | J15: début* | K15: totalité | L15: indéterminé | M15: autre | N15: allocutaire(s) | O15: allocutaire(s) | P15: non | R15: marqueur>portée | S15: ML | T15: positive
A16: 20017 | B16: REU_AC2 | C16: 2017 | D16: Réunion professionnelle | E16: 1431198 | F16: 1431300 | G16: AVOIR L'AIR | H16: locution verbale | I16: construction attributive à verbe copule | J16: milieu | K16: milieu | L16: indéterminé | M16: objet (symbolique) | N16: objet (symbolique) | O16: objet (symbolique) | P16: non | R16: à l'intérieur | S16: ML | T16: positive
A17: 20018 | B17: REU_CL1 | C17: 2017 | D17: Réunion professionnelle | E17: 2522231 | F17: 2522644 | G17: AVOIR L'AIR | H17: locution verbale | I17: construction attributive à verbe copule | J17: milieu | K17: totalité | L17: réactif/évaluatif | M17: allocutaire(s) | N17: allocutaire(s) | O17: allocutaire(s) | P17: non | R17: à l'intérieur | S17: ML | T17: positive
A18: 20019 | B18: REU_CL1 | C18: 2017 | D18: Réunion professionnelle | E18: 3934802 | F18: 3935249 | G18: AVOIR L'AIR | H18: locution verbale | I18: construction attributive à verbe copule | J18: début* | K18: totalité | L18: indéterminé | M18: autre | N18: allocutaire(s) | O18: allocutaire(s) | P18: non | R18: à l'intérieur | S18: ML | T18: positive
A19: 20020 | B19: REU_CL1 | C19: 2017 | D19: Réunion professionnelle | E19: 20296 | F19: 20648 | G19: AVOIR L'AIR | H19: locution verbale | I19: construction attributive à verbe copule | J19: milieu | K19: totalité | L19: indéterminé | M19: objet (symbolique) | N19: objet (symbolique) | O19: objet (symbolique) | P19: non | R19: à l'intérieur | S19: ML | T19: positive
A20: 20021 | B20: REU_CL1 | C20: 2017 | D20: Réunion professionnelle | E20: 5777249 | F20: 5777423 | G20: AVOIR L'AIR | H20: locution verbale | I20: construction attributive à verbe copule | J20: milieu | K20: milieu | L20: indéterminé | M20: allocutaire(s) | N20: autre | O20: autre | P20: non | R20: à l'intérieur | S20: ML | T20: positive
A21: 20023 | B21: REU_BL2 | C21: 2017 | D21: Réunion professionnelle | E21: 2018074 | F21: 2018700 | G21: AVOIR L'IMPRESSION | H21: locution verbale | I21: prédicat verbal à complément | J21: milieu | K21: milieu | L21: indéterminé | M21: autre | N21: autre | O21: autre | P21: oui | Q21: Meta.Cup | R21: marqueur>portée | S21: ML | T21: positive
A22: 20024 | B22: REU_BL2 | C22: 2017 | D22: Réunion professionnelle | E22: 2094604 | F22: 2095183 | G22: AVOIR L'IMPRESSION | H22: locution verbale | I22: prédicat verbal à complément | J22: milieu | K22: milieu | L22: indéterminé | M22: allocutaire(s) | N22: autre | O22: autre | P22: oui | Q22: Deictic.Addressee; Emblem.So-What | R22: marqueur>portée | S22: ML | T22: positive
A23: 20025 | B23: REU_BL2 | C23: 2017 | D23: Réunion professionnelle | E23: 1452304 | F23: 1452888 | G23: AVOIR L'IMPRESSION | H23: locution verbale | I23: prédicat verbal à complément | J23: milieu | K23: fin | L23: indéterminé | M23: allocutaire(s) | N23: allocutaire(s) | O23: allocutaire(s) | P23: oui | Q23: Deictic.Indeterminable | R23: marqueur>portée | S23: ML | T23: négative
A24: 20026 | B24: REU_BM1 | C24: 2017 | D24: Réunion professionnelle | E24: 3267596 | F24: 3269069 | G24: AVOIR L'IMPRESSION | H24: locution verbale | I24: prédicat verbal à complément | J24: début* | K24: milieu | L24: indéterminé | M24: allocutaire(s) | N24: autre | O24: allocutaire(s) | P24: oui | Q24: Deictic.Addressee | R24: marqueur>portée | S24: ML | T24: neutre
A25: 20027 | B25: REU_BM1 | C25: 2017 | D25: Réunion professionnelle | E25: 4398999 | F25: 4399496 | G25: AVOIR L'IMPRESSION | H25: locution verbale | I25: prédicat verbal à complément | J25: milieu | K25: milieu | L25: indéterminé | M25: objet (symbolique) | N25: allocutaire(s) | O25: allocutaire(s) | P25: oui | Q25: Deictic.Object | R25: marqueur>portée | S25: ML | T25: positive
A26: 20028 | B26: REU_BM2 | C26: 2017 | D26: Réunion professionnelle | E26: 2307546 | F26: 2308298 | G26: AVOIR L'IMPRESSION | H26: locution verbale | I26: prédicat verbal à complément | J26: début | K26: milieu | L26: indéterminé | M26: objet (symbolique) | N26: objet (symbolique) | O26: objet (symbolique) | P26: oui | Q26: Deictic.Object | R26: marqueur>portée | S26: ML | T26: positive
A27: 20029 | B27: REU_BV1 | C27: 2017 | D27: Réunion professionnelle | E27: 2706730 | F27: 2708308 | G27: AVOIR L'IMPRESSION | H27: locution verbale | I27: prédicat verbal à complément | J27: milieu | K27: milieu | L27: indéterminé | M27: autre | N27: allocutaire(s) | O27: autre | P27: non | R27: marqueur>portée | S27: ML | T27: positive
A28: 20030 | B28: REU_BV1 | C28: 2017 | D28: Réunion professionnelle | E28: 2747113 | F28: 2749083 | G28: AVOIR L'IMPRESSION | H28: locution verbale | I28: prédicat verbal à complément | J28: milieu | K28: totalité | L28: indéterminé | M28: autre | N28: allocutaire(s) | O28: allocutaire(s) | P28: oui | Q28: Deictic.Object | R28: marqueur>portée | S28: ML | T28: positive
A29: 20031 | B29: REU_BV1 | C29: 2017 | D29: Réunion professionnelle | E29: 5123100 | F29: 5123978 | G29: AVOIR L'IMPRESSION | H29: locution verbale | I29: prédicat verbal à complément | J29: début | K29: totalité | L29: réactif/évaluatif | M29: allocutaire(s) | N29: allocutaire(s) | O29: allocutaire(s) | P29: non | R29: marqueur>portée | S29: ML | T29: positive
A30: 20032 | B30: REU_CL1 | C30: 2017 | D30: Réunion professionnelle | E30: 1946101 | F30: 1946835 | G30: AVOIR L'IMPRESSION | H30: locution verbale | I30: prédicat verbal à complément | J30: milieu | K30: fin | L30: réactif/évaluatif | M30: allocutaire(s) | N30: allocutaire(s) | O30: allocutaire(s) | P30: non | R30: marqueur>portée | S30: ML | T30: positive
A31: 20033 | B31: REU_CL1 | C31: 2017 | D31: Réunion professionnelle | E31: 3625300 | F31: 3626886 | G31: AVOIR L'IMPRESSION | H31: locution verbale | I31: prédicat verbal à complément | J31: début* | K31: milieu | L31: indéterminé | M31: autre | N31: autre | O31: autre | P31: non | R31: marqueur>portée | S31: ML | T31: positive
A32: 20034 | B32: REU_CL4 | C32: 2018 | D32: Réunion professionnelle | E32: 164459 | F32: 165002 | G32: AVOIR L'IMPRESSION | H32: locution verbale | I32: prédicat verbal à complément | J32: début* | K32: milieu | L32: initiatif | M32: autre | N32: autre | O32: autre | P32: non | R32: marqueur>portée | S32: ML | T32: positive
A33: 20035 | B33: REU_CL4 | C33: 2018 | D33: Réunion professionnelle | E33: 1751370 | F33: 1752333 | G33: AVOIR L'IMPRESSION | H33: locution verbale | I33: parenthétique | J33: fin | K33: totalité | L33: réactif/évaluatif | M33: objet (symbolique) | N33: objet (symbolique) | O33: objet (symbolique) | P33: non | R33: portée<marqueur | S33: ML | T33: positive
A34: 20036 | B34: REU_CL4 | C34: 2018 | D34: Réunion professionnelle | E34: 3502810 | F34: 3503557 | G34: AVOIR L'IMPRESSION | H34: locution verbale | I34: parenthétique | J34: fin | K34: fin | L34: indéterminé | M34: autre | N34: autre | O34: allocutaire(s) | P34: non | R34: portée<marqueur | S34: ML | T34: positive
A35: 20037 | B35: REU_CL4 | C35: 2018 | D35: Réunion professionnelle | E35: 5730225 | F35: 5731572 | G35: AVOIR L'IMPRESSION | H35: locution verbale | I35: prédicat verbal à complément | J35: milieu | K35: fin | L35: indéterminé | M35: indéterminable | N35: indéterminable | O35: indéterminable | P35: non | R35: marqueur>portée | S35: ML | T35: positive
A36: 20038 | B36: REU_AM1 | C36: 2017 | D36: Réunion professionnelle | E36: 2250859 | F36: 2251618 | G36: AVOIR L'IMPRESSION | H36: locution verbale | I36: prédicat verbal à complément | J36: milieu | K36: totalité | L36: réactif/évaluatif | M36: autre | N36: autre | O36: allocutaire(s) | P36: oui | Q36: Deictic.Object | R36: marqueur>portée | S36: ML | T36: positive
A37: 20039 | B37: REU_BL1 | C37: 2017 | D37: Réunion professionnelle | E37: 1082360 | F37: 1083470 | G37: DONNER L'IMPRESSION | H37: locution verbale | I37: construction attributive à verbe copule | J37: milieu | K37: totalité | L37: indéterminé | M37: allocutaire(s) | N37: allocutaire(s) | O37: allocutaire(s) | P37: oui | Q37: Deictic.Addressee; Meta.Thought-Grip | R37: à l'intérieur | S37: ML | T37: positive
A38: 20040 | B38: REU_BL2 | C38: 2017 | D38: Réunion professionnelle | E38: 1235904 | F38: 1237273 | G38: DONNER L'IMPRESSION | H38: locution verbale | I38: proposition complète | J38: totalité | K38: totalité | L38: indéterminé | M38: autre | N38: allocutaire(s) | O38: autre | P38: oui | Q38: Meta.Thought-Grip | R38: portée<marqueur | S38: ML | T38: positive
A39: 20041 | B39: REU_AM1 | C39: 2017 | D39: Réunion professionnelle | E39: 2434645 | F39: 2435838 | G39: DONNER L'IMPRESSION | H39: locution verbale | I39: construction attributive à verbe copule | J39: totalité | K39: fin | L39: indéterminé | M39: objet (symbolique) | N39: allocutaire(s) | O39: allocutaire(s) | P39: non | R39: portée<marqueur | S39: ML | T39: positive
A40: 20042 | B40: DTV_REC | C40: 2009 | D40: Débat télévisé | E40: 2493425 | F40: 2493607 | G40: PARAÎTRE | H40: verbe | I40: construction attributive à verbe copule | J40: début* | K40: totalité | L40: réactif/évaluatif | M40: indéterminable | N40: indéterminable | O40: indéterminable | P40: impossible à déterminer | R40: à l'intérieur | S40: ML | T40: positive
...

Sheet TOKEN PAR PERS_ONTO
A1: Personnes ontologiques | B1: AVOIR L'AIR | C1: AVOIR L'IMPRESSION | D1: DONNER L'IMPRESSION | E1: PARAITRE | F1: SEMBLER | G1: APPAREMMENT | H1: EVIDEMMENT | I1: MANIFESTEMENT | J1: VISIBLEMENT | K1: TOTAL | L1: Temps de parole total personnes ontologiques | M1: avoir l'air [look like] per 10 min | N1: avoir l'impression [feel] per 10 min | O1: donner l'impression [give the impression] per 10 min | P1: paraître [appear] per 10 min | Q1: sembler [seem] per 10 min | R1: apparemment [apparently] per 10 min | S1: évidemment [obviously] per 10 min | T1: manifestement [clearly] per 10 min | U1: visiblement [visibly] per 10 min | V1: Total par 10 min
A2: CH1 | C2: 1 | E2: 6 | F2: 16 | K2: =SUM(B2:J2) -> 23 | L2: =_xlfn.XLOOKUP(Tableau3[[#This Row],[Personnes ontologiques]],'TEMPS PAROLE PERS_ONTO'!A:A,'TEMPS PAROLE PERS_ONTO'!B:B) -> 2260.48 | M2: =Tableau3[[#This Row],[AVOIR L''AIR]]/Tableau3[[#This Row],[Temps de parole total personnes ontologiques]]*600 -> 0 | N2: =Tableau3[[#This Row],[AVOIR L''IMPRESSION]]/Tableau3[[#This Row],[Temps de parole total personnes ontologiques]]*600 -> 0.26543035 | O2: =Tableau3[[#This Row],[DONNER L''IMPRESSION]]/Tableau3[[#This Row],[Temps de parole total personnes ontologiques]]*600 -> 0 | P2: =Tableau3[[#This Row],[PARAITRE]]/Tableau3[[#This Row],[Temps de parole total personnes ontologiques]]*600 -> 1.5925821 | Q2: =Tableau3[[#This Row],[SEMBLER]]/Tableau3[[#This Row],[Temps de parole total personnes ontologiques]]*600 -> 4.2468856 | R2: =Tableau3[[#This Row],[APPAREMMENT]]/Tableau3[[#This Row],[Temps de parole total personnes ontologiques]]*600 -> 0 | S2: =Tableau3[[#This Row],[EVIDEMMENT]]/Tableau3[[#This Row],[Temps de parole total personnes ontologiques]]*600 -> 0 | T2: =Tableau3[[#This Row],[MANIFESTEMENT]]/Tableau3[[#This Row],[Temps de parole total personnes ontologiques]]*600 -> 0 | U2: =Tableau3[[#This Row],[VISIBLEMENT]]/Tableau3[[#This Row],[Temps de parole total personnes ontologiques]]*600 -> 0 | V2: =SUM(Tableau3[[#This Row],[avoir l''air '[look like'] per 10 min]:[visiblement '[visibly'] per 10 min]]) -> 6.1048981 | X2: ISA = stagiaire, AC1 et suite à un téléphone pendant la réunion, elle dit : <((parle à jean)) elle t'avait apparemment elle t'avait appelé la semaine dernière> ; au total elle s'exprime 18 secondes ; intéressant // à statut et // public
A3: DOL | E3: 1 | H3: 18 | K3: =SUM(B3:J3) -> 19 | L3: =_xlfn.XLOOKUP(Tableau3[[#This Row],[Personnes ontologiques]],'TEMPS PAROLE PERS_ONTO'!A:A,'TEMPS PAROLE PERS_ONTO'!B:B) -> 1707.597 | M3: =Tableau3[[#This Row],[AVOIR L''AIR]]/Tableau3[[#This Row],[Temps de parole total personnes ontologiques]]*600 -> 0 | N3: =Tableau3[[#This Row],[AVOIR L''IMPRESSION]]/Tableau3[[#This Row],[Temps de parole total personnes ontologiques]]*600 -> 0 | O3: =Tableau3[[#This Row],[DONNER L''IMPRESSION]]/Tableau3[[#This Row],[Temps de parole total personnes ontologiques]]*600 -> 0 | P3: =Tableau3[[#This Row],[PARAITRE]]/Tableau3[[#This Row],[Temps de parole total personnes ontologiques]]*600 -> 0.35137096 | Q3: =Tableau3[[#This Row],[SEMBLER]]/Tableau3[[#This Row],[Temps de parole total personnes ontologiques]]*600 -> 0 | R3: =Tableau3[[#This Row],[APPAREMMENT]]/Tableau3[[#This Row],[Temps de parole total personnes ontologiques]]*600 -> 0 | S3: =Tableau3[[#This Row],[EVIDEMMENT]]/Tableau3[[#This Row],[Temps de parole total personnes ontologiques]]*600 -> 6.3246773 | T3: =Tableau3[[#This Row],[MANIFESTEMENT]]/Tableau3[[#This Row],[Temps de parole total personnes ontologiques]]*600 -> 0 | U3: =Tableau3[[#This Row],[VISIBLEMENT]]/Tableau3[[#This Row],[Temps de parole total personnes ontologiques]]*600 -> 0 | V3: =SUM(Tableau3[[#This Row],[avoir l''air '[look like'] per 10 min]:[visiblement '[visibly'] per 10 min]]) -> 6.6760483
A4: SAN | B4: 4 | H4: 15 | K4: =SUM(B4:J4) -> 19 | L4: =_xlfn.XLOOKUP(Tableau3[[#This Row],[Personnes ontologiques]],'TEMPS PAROLE PERS_ONTO'!A:A,'TEMPS PAROLE PERS_ONTO'!B:B) -> 1863.615 | M4: =Tableau3[[#This Row],[AVOIR L''AIR]]/Tableau3[[#This Row],[Temps de parole total personnes ontologiques]]*600 -> 1.2878196 | N4: =Tableau3[[#This Row],[AVOIR L''IMPRESSION]]/Tableau3[[#This Row],[Temps de parole total personnes ontologiques]]*600 -> 0 | O4: =Tableau3[[#This Row],[DONNER L''IMPRESSION]]/Tableau3[[#This Row],[Temps de parole total personnes ontologiques]]*600 -> 0 | P4: =Tableau3[[#This Row],[PARAITRE]]/Tableau3[[#This Row],[Temps de parole total personnes ontologiques]]*600 -> 0 | Q4: =Tableau3[[#This Row],[SEMBLER]]/Tableau3[[#This Row],[Temps de parole total personnes ontologiques]]*600 -> 0 | R4: =Tableau3[[#This Row],[APPAREMMENT]]/Tableau3[[#This Row],[Temps de parole total personnes ontologiques]]*600 -> 0 | S4: =Tableau3[[#This Row],[EVIDEMMENT]]/Tableau3[[#This Row],[Temps de parole total personnes ontologiques]]*600 -> 4.8293237 | T4: =Tableau3[[#This Row],[MANIFESTEMENT]]/Tableau3[[#This Row],[Temps de parole total personnes ontologiques]]*600 -> 0 | U4: =Tableau3[[#This Row],[VISIBLEMENT]]/Tableau3[[#This Row],[Temps de parole total personnes ontologiques]]*600 -> 0 | V4: =SUM(Tableau3[[#This Row],[avoir l''air '[look like'] per 10 min]:[visiblement '[visibly'] per 10 min]]) -> 6.1171433
A5: NA1 | E5: 3 | F5: 1 | H5: 8 | J5: 1 | K5: =SUM(B5:J5) -> 13 | L5: =_xlfn.XLOOKUP(Tableau3[[#This Row],[Personnes ontologiques]],'TEMPS PAROLE PERS_ONTO'!A:A,'TEMPS PAROLE PERS_ONTO'!B:B) -> 3740.337 | M5: =Tableau3[[#This Row],[AVOIR L''AIR]]/Tableau3[[#This Row],[Temps de parole total personnes ontologiques]]*600 -> 0 | N5: =Tableau3[[#This Row],[AVOIR L''IMPRESSION]]/Tableau3[[#This Row],[Temps de parole total personnes ontologiques]]*600 -> 0 | O5: =Tableau3[[#This Row],[DONNER L''IMPRESSION]]/Tableau3[[#This Row],[Temps de parole total personnes ontologiques]]*600 -> 0 | P5: =Tableau3[[#This Row],[PARAITRE]]/Tableau3[[#This Row],[Temps de parole total personnes ontologiques]]*600 -> 0.48124006 | Q5: =Tableau3[[#This Row],[SEMBLER]]/Tableau3[[#This Row],[Temps de parole total personnes ontologiques]]*600 -> 0.16041335 | R5: =Tableau3[[#This Row],[APPAREMMENT]]/Tableau3[[#This Row],[Temps de parole total personnes ontologiques]]*600 -> 0 | S5: =Tableau3[[#This Row],[EVIDEMMENT]]/Tableau3[[#This Row],[Temps de parole total personnes ontologiques]]*600 -> 1.2833068 | T5: =Tableau3[[#This Row],[MANIFESTEMENT]]/Tableau3[[#This Row],[Temps de parole total personnes ontologiques]]*600 -> 0 | U5: =Tableau3[[#This Row],[VISIBLEMENT]]/Tableau3[[#This Row],[Temps de parole total personnes ontologiques]]*600 -> 0.16041335 | V5: =SUM(Tableau3[[#This Row],[avoir l''air '[look like'] per 10 min]:[visiblement '[visibly'] per 10 min]]) -> 2.0853736
A6: OLR | B6: 3 | C6: 3 | E6: 1 | F6: 2 | G6: 3 | K6: =SUM(B6:J6) -> 12 | L6: =_xlfn.XLOOKUP(Tableau3[[#This Row],[Personnes ontologiques]],'TEMPS PAROLE PERS_ONTO'!A:A,'TEMPS PAROLE PERS_ONTO'!B:B) -> 1504.597 | M6: =Tableau3[[#This Row],[AVOIR L''AIR]]/Tableau3[[#This Row],[Temps de parole total personnes ontologiques]]*600 -> 1.1963336 | N6: =Tableau3[[#This Row],[AVOIR L''IMPRESSION]]/Tableau3[[#This Row],[Temps de parole total personnes ontologiques]]*600 -> 1.1963336 | O6: =Tableau3[[#This Row],[DONNER L''IMPRESSION]]/Tableau3[[#This Row],[Temps de parole total personnes ontologiques]]*600 -> 0 | P6: =Tableau3[[#This Row],[PARAITRE]]/Tableau3[[#This Row],[Temps de parole total personnes ontologiques]]*600 -> 0.39877788 | Q6: =Tableau3[[#This Row],[SEMBLER]]/Tableau3[[#This Row],[Temps de parole total personnes ontologiques]]*600 -> 0.79755576 | R6: =Tableau3[[#This Row],[APPAREMMENT]]/Tableau3[[#This Row],[Temps de parole total personnes ontologiques]]*600 -> 1.1963336 | S6: =Tableau3[[#This Row],[EVIDEMMENT]]/Tableau3[[#This Row],[Temps de parole total personnes ontologiques]]*600 -> 0 | T6: =Tableau3[[#This Row],[MANIFESTEMENT]]/Tableau3[[#This Row],[Temps de parole total personnes ontologiques]]*600 -> 0 | U6: =Tableau3[[#This Row],[VISIBLEMENT]]/Tableau3[[#This Row],[Temps de parole total personnes ontologiques]]*600 -> 0 | V6: =SUM(Tableau3[[#This Row],[avoir l''air '[look like'] per 10 min]:[visiblement '[visibly'] per 10 min]]) -> 4.7853345
A7: YVA | C7: 3 | F7: 3 | H7: 5 | J7: 1 | K7: =SUM(B7:J7) -> 12 | L7: =_xlfn.XLOOKUP(Tableau3[[#This Row],[Personnes ontologiques]],'TEMPS PAROLE PERS_ONTO'!A:A,'TEMPS PAROLE PERS_ONTO'!B:B) -> 2715.902 | M7: =Tableau3[[#This Row],[AVOIR L''AIR]]/Tableau3[[#This Row],[Temps de parole total personnes ontologiques]]*600 -> 0 | N7: =Tableau3[[#This Row],[AVOIR L''IMPRESSION]]/Tableau3[[#This Row],[Temps de parole total personnes ontologiques]]*600 -> 0.66276324 | O7: =Tableau3[[#This Row],[DONNER L''IMPRESSION]]/Tableau3[[#This Row],[Temps de parole total personnes ontologiques]]*600 -> 0 | P7: =Tableau3[[#This Row],[PARAITRE]]/Tableau3[[#This Row],[Temps de parole total personnes ontologiques]]*600 -> 0 | Q7: =Tableau3[[#This Row],[SEMBLER]]/Tableau3[[#This Row],[Temps de parole total personnes ontologiques]]*600 -> 0.66276324 | R7: =Tableau3[[#This Row],[APPAREMMENT]]/Tableau3[[#This Row],[Temps de parole total personnes ontologiques]]*600 -> 0 | S7: =Tableau3[[#This Row],[EVIDEMMENT]]/Tableau3[[#This Row],[Temps de parole total personnes ontologiques]]*600 -> 1.1046054 | T7: =Tableau3[[#This Row],[MANIFESTEMENT]]/Tableau3[[#This Row],[Temps de parole total personnes ontologiques]]*600 -> 0 | U7: =Tableau3[[#This Row],[VISIBLEMENT]]/Tableau3[[#This Row],[Temps de parole total personnes ontologiques]]*600 -> 0.22092108 | V7: =SUM(Tableau3[[#This Row],[avoir l''air '[look like'] per 10 min]:[visiblement '[visibly'] per 10 min]]) -> 2.6510529
A8: P16 | C8: 1 | F8: 10 | K8: =SUM(B8:J8) -> 11 | L8: =_xlfn.XLOOKUP(Tableau3[[#This Row],[Personnes ontologiques]],'TEMPS PAROLE PERS_ONTO'!A:A,'TEMPS PAROLE PERS_ONTO'!B:B) -> 286.621 | M8: =Tableau3[[#This Row],[AVOIR L''AIR]]/Tableau3[[#This Row],[Temps de parole total personnes ontologiques]]*600 -> 0 | N8: =Tableau3[[#This Row],[AVOIR L''IMPRESSION]]/Tableau3[[#This Row],[Temps de parole total personnes ontologiques]]*600 -> 2.0933567 | O8: =Tableau3[[#This Row],[DONNER L''IMPRESSION]]/Tableau3[[#This Row],[Temps de parole total personnes ontologiques]]*600 -> 0 | P8: =Tableau3[[#This Row],[PARAITRE]]/Tableau3[[#This Row],[Temps de parole total personnes ontologiques]]*600 -> 0 | Q8: =Tableau3[[#This Row],[SEMBLER]]/Tableau3[[#This Row],[Temps de parole total personnes ontologiques]]*600 -> 20.933567 | R8: =Tableau3[[#This Row],[APPAREMMENT]]/Tableau3[[#This Row],[Temps de parole total personnes ontologiques]]*600 -> 0 | S8: =Tableau3[[#This Row],[EVIDEMMENT]]/Tableau3[[#This Row],[Temps de parole total personnes ontologiques]]*600 -> 0 | T8: =Tableau3[[#This Row],[MANIFESTEMENT]]/Tableau3[[#This Row],[Temps de parole total personnes ontologiques]]*600 -> 0 | U8: =Tableau3[[#This Row],[VISIBLEMENT]]/Tableau3[[#This Row],[Temps de parole total personnes ontologiques]]*600 -> 0 | V8: =SUM(Tableau3[[#This Row],[avoir l''air '[look like'] per 10 min]:[visiblement '[visibly'] per 10 min]]) -> 23.026924
A9: P52 | C9: 1 | F9: 5 | H9: 2 | J9: 3 | K9: =SUM(B9:J9) -> 11 | L9: =_xlfn.XLOOKUP(Tableau3[[#This Row],[Personnes ontologiques]],'TEMPS PAROLE PERS_ONTO'!A:A,'TEMPS PAROLE PERS_ONTO'!B:B) -> 495.172 | M9: =Tableau3[[#This Row],[AVOIR L''AIR]]/Tableau3[[#This Row],[Temps de parole total personnes ontologiques]]*600 -> 0 | N9: =Tableau3[[#This Row],[AVOIR L''IMPRESSION]]/Tableau3[[#This Row],[Temps de parole total personnes ontologiques]]*600 -> 1.2117002 | O9: =Tableau3[[#This Row],[DONNER L''IMPRESSION]]/Tableau3[[#This Row],[Temps de parole total personnes ontologiques]]*600 -> 0 | P9: =Tableau3[[#This Row],[PARAITRE]]/Tableau3[[#This Row],[Temps de parole total personnes ontologiques]]*600 -> 0 | Q9: =Tableau3[[#This Row],[SEMBLER]]/Tableau3[[#This Row],[Temps de parole total personnes ontologiques]]*600 -> 6.0585009 | R9: =Tableau3[[#This Row],[APPAREMMENT]]/Tableau3[[#This Row],[Temps de parole total personnes ontologiques]]*600 -> 0 | S9: =Tableau3[[#This Row],[EVIDEMMENT]]/Tableau3[[#This Row],[Temps de parole total personnes ontologiques]]*600 -> 2.4234004 | T9: =Tableau3[[#This Row],[MANIFESTEMENT]]/Tableau3[[#This Row],[Temps de parole total personnes ontologiques]]*600 -> 0 | U9: =Tableau3[[#This Row],[VISIBLEMENT]]/Tableau3[[#This Row],[Temps de parole total personnes ontologiques]]*600 -> 3.6351005 | V9: =SUM(Tableau3[[#This Row],[avoir l''air '[look like'] per 10 min]:[visiblement '[visibly'] per 10 min]]) -> 13.328702
A10: BRI | B10: 1 | C10: 4 | F10: 2 | G10: 1 | H10: 2 | K10: =SUM(B10:J10) -> 10 | L10: =_xlfn.XLOOKUP(Tableau3[[#This Row],[Personnes ontologiques]],'TEMPS PAROLE PERS_ONTO'!A:A,'TEMPS PAROLE PERS_ONTO'!B:B) -> 1324.671 | M10: =Tableau3[[#This Row],[AVOIR L''AIR]]/Tableau3[[#This Row],[Temps de parole total personnes ontologiques]]*600 -> 0.45294266 | N10: =Tableau3[[#This Row],[AVOIR L''IMPRESSION]]/Tableau3[[#This Row],[Temps de parole total personnes ontologiques]]*600 -> 1.8117706 | O10: =Tableau3[[#This Row],[DONNER L''IMPRESSION]]/Tableau3[[#This Row],[Temps de parole total personnes ontologiques]]*600 -> 0 | P10: =Tableau3[[#This Row],[PARAITRE]]/Tableau3[[#This Row],[Temps de parole total personnes ontologiques]]*600 -> 0 | Q10: =Tableau3[[#This Row],[SEMBLER]]/Tableau3[[#This Row],[Temps de parole total personnes ontologiques]]*600 -> 0.90588531 | R10: =Tableau3[[#This Row],[APPAREMMENT]]/Tableau3[[#This Row],[Temps de parole total personnes ontologiques]]*600 -> 0.45294266 | S10: =Tableau3[[#This Row],[EVIDEMMENT]]/Tableau3[[#This Row],[Temps de parole total personnes ontologiques]]*600 -> 0.90588531 | T10: =Tableau3[[#This Row],[MANIFESTEMENT]]/Tableau3[[#This Row],[Temps de parole total personnes ontologiques]]*600 -> 0 | U10: =Tableau3[[#This Row],[VISIBLEMENT]]/Tableau3[[#This Row],[Temps de parole total personnes ontologiques]]*600 -> 0 | V10: =SUM(Tableau3[[#This Row],[avoir l''air '[look like'] per 10 min]:[visiblement '[visibly'] per 10 min]]) -> 4.5294266
A11: BOR | B11: 1 | C11: 3 | D11: 1 | E11: 3 | J11: 1 | K11: =SUM(B11:J11) -> 9 | L11: =_xlfn.XLOOKUP(Tableau3[[#This Row],[Personnes ontologiques]],'TEMPS PAROLE PERS_ONTO'!A:A,'TEMPS PAROLE PERS_ONTO'!B:B) -> 3916.654 | M11: =Tableau3[[#This Row],[AVOIR L''AIR]]/Tableau3[[#This Row],[Temps de parole total personnes ontologiques]]*600 -> 0.15319198 | N11: =Tableau3[[#This Row],[AVOIR L''IMPRESSION]]/Tableau3[[#This Row],[Temps de parole total personnes ontologiques]]*600 -> 0.45957595 | O11: =Tableau3[[#This Row],[DONNER L''IMPRESSION]]/Tableau3[[#This Row],[Temps de parole total personnes ontologiques]]*600 -> 0.15319198 | P11: =Tableau3[[#This Row],[PARAITRE]]/Tableau3[[#This Row],[Temps de parole total personnes ontologiques]]*600 -> 0.45957595 | Q11: =Tableau3[[#This Row],[SEMBLER]]/Tableau3[[#This Row],[Temps de parole total personnes ontologiques]]*600 -> 0 | R11: =Tableau3[[#This Row],[APPAREMMENT]]/Tableau3[[#This Row],[Temps de parole total personnes ontologiques]]*600 -> 0 | S11: =Tableau3[[#This Row],[EVIDEMMENT]]/Tableau3[[#This Row],[Temps de parole total personnes ontologiques]]*600 -> 0 | T11: =Tableau3[[#This Row],[MANIFESTEMENT]]/Tableau3[[#This Row],[Temps de parole total personnes ontologiques]]*600 -> 0 | U11: =Tableau3[[#This Row],[VISIBLEMENT]]/Tableau3[[#This Row],[Temps de parole total personnes ontologiques]]*600 -> 0.15319198 | V11: =SUM(Tableau3[[#This Row],[avoir l''air '[look like'] per 10 min]:[visiblement '[visibly'] per 10 min]]) -> 1.3787279
A12: FLO | C12: 3 | D12: 2 | E12: 1 | F12: 1 | K12: =SUM(B12:J12) -> 7 | L12: =_xlfn.XLOOKUP(Tableau3[[#This Row],[Personnes ontologiques]],'TEMPS PAROLE PERS_ONTO'!A:A,'TEMPS PAROLE PERS_ONTO'!B:B) -> 749.336 | M12: =Tableau3[[#This Row],[AVOIR L''AIR]]/Tableau3[[#This Row],[Temps de parole total personnes ontologiques]]*600 -> 0 | N12: =Tableau3[[#This Row],[AVOIR L''IMPRESSION]]/Tableau3[[#This Row],[Temps de parole total personnes ontologiques]]*600 -> 2.4021267 | O12: =Tableau3[[#This Row],[DONNER L''IMPRESSION]]/Tableau3[[#This Row],[Temps de parole total personnes ontologiques]]*600 -> 1.6014178 | P12: =Tableau3[[#This Row],[PARAITRE]]/Tableau3[[#This Row],[Temps de parole total personnes ontologiques]]*600 -> 0.80070889 | Q12: =Tableau3[[#This Row],[SEMBLER]]/Tableau3[[#This Row],[Temps de parole total personnes ontologiques]]*600 -> 0.80070889 | R12: =Tableau3[[#This Row],[APPAREMMENT]]/Tableau3[[#This Row],[Temps de parole total personnes ontologiques]]*600 -> 0 | S12: =Tableau3[[#This Row],[EVIDEMMENT]]/Tableau3[[#This Row],[Temps de parole total personnes ontologiques]]*600 -> 0 | T12: =Tableau3[[#This Row],[MANIFESTEMENT]]/Tableau3[[#This Row],[Temps de parole total personnes ontologiques]]*600 -> 0 | U12: =Tableau3[[#This Row],[VISIBLEMENT]]/Tableau3[[#This Row],[Temps de parole total personnes ontologiques]]*600 -> 0 | V12: =SUM(Tableau3[[#This Row],[avoir l''air '[look like'] per 10 min]:[visiblement '[visibly'] per 10 min]]) -> 5.6049623
A13: LEV | E13: 2 | F13: 3 | H13: 2 | K13: =SUM(B13:J13) -> 7 | L13: =_xlfn.XLOOKUP(Tableau3[[#This Row],[Personnes ontologiques]],'TEMPS PAROLE PERS_ONTO'!A:A,'TEMPS PAROLE PERS_ONTO'!B:B) -> 921.239 | M13: =Tableau3[[#This Row],[AVOIR L''AIR]]/Tableau3[[#This Row],[Temps de parole total personnes ontologiques]]*600 -> 0 | N13: =Tableau3[[#This Row],[AVOIR L''IMPRESSION]]/Tableau3[[#This Row],[Temps de parole total personnes ontologiques]]*600 -> 0 | O13: =Tableau3[[#This Row],[DONNER L''IMPRESSION]]/Tableau3[[#This Row],[Temps de parole total personnes ontologiques]]*600 -> 0 | P13: =Tableau3[[#This Row],[PARAITRE]]/Tableau3[[#This Row],[Temps de parole total personnes ontologiques]]*600 -> 1.3025936 | Q13: =Tableau3[[#This Row],[SEMBLER]]/Tableau3[[#This Row],[Temps de parole total personnes ontologiques]]*600 -> 1.9538904 | R13: =Tableau3[[#This Row],[APPAREMMENT]]/Tableau3[[#This Row],[Temps de parole total personnes ontologiques]]*600 -> 0 | S13: =Tableau3[[#This Row],[EVIDEMMENT]]/Tableau3[[#This Row],[Temps de parole total personnes ontologiques]]*600 -> 1.3025936 | T13: =Tableau3[[#This Row],[MANIFESTEMENT]]/Tableau3[[#This Row],[Temps de parole total personnes ontologiques]]*600 -> 0 | U13: =Tableau3[[#This Row],[VISIBLEMENT]]/Tableau3[[#This Row],[Temps de parole total personnes ontologiques]]*600 -> 0 | V13: =SUM(Tableau3[[#This Row],[avoir l''air '[look like'] per 10 min]:[visiblement '[visibly'] per 10 min]]) -> 4.5590775
A14: AN2 | F14: 3 | H14: 3 | K14: =SUM(B14:J14) -> 6 | L14: =_xlfn.XLOOKUP(Tableau3[[#This Row],[Personnes ontologiques]],'TEMPS PAROLE PERS_ONTO'!A:A,'TEMPS PAROLE PERS_ONTO'!B:B) -> 559.061 | M14: =Tableau3[[#This Row],[AVOIR L''AIR]]/Tableau3[[#This Row],[Temps de parole total personnes ontologiques]]*600 -> 0 | N14: =Tableau3[[#This Row],[AVOIR L''IMPRESSION]]/Tableau3[[#This Row],[Temps de parole total personnes ontologiques]]*600 -> 0 | O14: =Tableau3[[#This Row],[DONNER L''IMPRESSION]]/Tableau3[[#This Row],[Temps de parole total personnes ontologiques]]*600 -> 0 | P14: =Tableau3[[#This Row],[PARAITRE]]/Tableau3[[#This Row],[Temps de parole total personnes ontologiques]]*600 -> 0 | Q14: =Tableau3[[#This Row],[SEMBLER]]/Tableau3[[#This Row],[Temps de parole total personnes ontologiques]]*600 -> 3.2196844 | R14: =Tableau3[[#This Row],[APPAREMMENT]]/Tableau3[[#This Row],[Temps de parole total personnes ontologiques]]*600 -> 0 | S14: =Tableau3[[#This Row],[EVIDEMMENT]]/Tableau3[[#This Row],[Temps de parole total personnes ontologiques]]*600 -> 3.2196844 | T14: =Tableau3[[#This Row],[MANIFESTEMENT]]/Tableau3[[#This Row],[Temps de parole total personnes ontologiques]]*600 -> 0 | U14: =Tableau3[[#This Row],[VISIBLEMENT]]/Tableau3[[#This Row],[Temps de parole total personnes ontologiques]]*600 -> 0 | V14: =SUM(Tableau3[[#This Row],[avoir l''air '[look like'] per 10 min]:[visiblement '[visibly'] per 10 min]]) -> 6.4393689
A15: BL1 | F15: 3 | H15: 3 | K15: =SUM(B15:J15) -> 6 | L15: =_xlfn.XLOOKUP(Tableau3[[#This Row],[Personnes ontologiques]],'TEMPS PAROLE PERS_ONTO'!A:A,'TEMPS PAROLE PERS_ONTO'!B:B) -> 1296.232 | M15: =Tableau3[[#This Row],[AVOIR L''AIR]]/Tableau3[[#This Row],[Temps de parole total personnes ontologiques]]*600 -> 0 | N15: =Tableau3[[#This Row],[AVOIR L''IMPRESSION]]/Tableau3[[#This Row],[Temps de parole total personnes ontologiques]]*600 -> 0 | O15: =Tableau3[[#This Row],[DONNER L''IMPRESSION]]/Tableau3[[#This Row],[Temps de parole total personnes ontologiques]]*600 -> 0 | P15: =Tableau3[[#This Row],[PARAITRE]]/Tableau3[[#This Row],[Temps de parole total personnes ontologiques]]*600 -> 0 | Q15: =Tableau3[[#This Row],[SEMBLER]]/Tableau3[[#This Row],[Temps de parole total personnes ontologiques]]*600 -> 1.3886403 | R15: =Tableau3[[#This Row],[APPAREMMENT]]/Tableau3[[#This Row],[Temps de parole total personnes ontologiques]]*600 -> 0 | S15: =Tableau3[[#This Row],[EVIDEMMENT]]/Tableau3[[#This Row],[Temps de parole total personnes ontologiques]]*600 -> 1.3886403 | T15: =Tableau3[[#This Row],[MANIFESTEMENT]]/Tableau3[[#This Row],[Temps de parole total personnes ontologiques]]*600 -> 0 | U15: =Tableau3[[#This Row],[VISIBLEMENT]]/Tableau3[[#This Row],[Temps de parole total personnes ontologiques]]*600 -> 0 | V15: =SUM(Tableau3[[#This Row],[avoir l''air '[look like'] per 10 min]:[visiblement '[visibly'] per 10 min]]) -> 2.7772806
A16: LOR | B16: 1 | E16: 1 | F16: 2 | H16: 2 | K16: =SUM(B16:J16) -> 6 | L16: =_xlfn.XLOOKUP(Tableau3[[#This Row],[Personnes ontologiques]],'TEMPS PAROLE PERS_ONTO'!A:A,'TEMPS PAROLE PERS_ONTO'!B:B) -> 1557.926 | M16: =Tableau3[[#This Row],[AVOIR L''AIR]]/Tableau3[[#This Row],[Temps de parole total personnes ontologiques]]*600 -> 0.38512741 | N16: =Tableau3[[#This Row],[AVOIR L''IMPRESSION]]/Tableau3[[#This Row],[Temps de parole total personnes ontologiques]]*600 -> 0 | O16: =Tableau3[[#This Row],[DONNER L''IMPRESSION]]/Tableau3[[#This Row],[Temps de parole total personnes ontologiques]]*600 -> 0 | P16: =Tableau3[[#This Row],[PARAITRE]]/Tableau3[[#This Row],[Temps de parole total personnes ontologiques]]*600 -> 0.38512741 | Q16: =Tableau3[[#This Row],[SEMBLER]]/Tableau3[[#This Row],[Temps de parole total personnes ontologiques]]*600 -> 0.77025481 | R16: =Tableau3[[#This Row],[APPAREMMENT]]/Tableau3[[#This Row],[Temps de parole total personnes ontologiques]]*600 -> 0 | S16: =Tableau3[[#This Row],[EVIDEMMENT]]/Tableau3[[#This Row],[Temps de parole total personnes ontologiques]]*600 -> 0.77025481 | T16: =Tableau3[[#This Row],[MANIFESTEMENT]]/Tableau3[[#This Row],[Temps de parole total personnes ontologiques]]*600 -> 0 | U16: =Tableau3[[#This Row],[VISIBLEMENT]]/Tableau3[[#This Row],[Temps de parole total personnes ontologiques]]*600 -> 0 | V16: =SUM(Tableau3[[#This Row],[avoir l''air '[look like'] per 10 min]:[visiblement '[visibly'] per 10 min]]) -> 2.3107644
A17: RAP | C17: 3 | F17: 1 | G17: 1 | H17: 1 | K17: =SUM(B17:J17) -> 6 | L17: =_xlfn.XLOOKUP(Tableau3[[#This Row],[Personnes ontologiques]],'TEMPS PAROLE PERS_ONTO'!A:A,'TEMPS PAROLE PERS_ONTO'!B:B) -> 2014.831 | M17: =Tableau3[[#This Row],[AVOIR L''AIR]]/Tableau3[[#This Row],[Temps de parole total personnes ontologiques]]*600 -> 0 | N17: =Tableau3[[#This Row],[AVOIR L''IMPRESSION]]/Tableau3[[#This Row],[Temps de parole total personnes ontologiques]]*600 -> 0.89337518 | O17: =Tableau3[[#This Row],[DONNER L''IMPRESSION]]/Tableau3[[#This Row],[Temps de parole total personnes ontologiques]]*600 -> 0 | P17: =Tableau3[[#This Row],[PARAITRE]]/Tableau3[[#This Row],[Temps de parole total personnes ontologiques]]*600 -> 0 | Q17: =Tableau3[[#This Row],[SEMBLER]]/Tableau3[[#This Row],[Temps de parole total personnes ontologiques]]*600 -> 0.29779173 | R17: =Tableau3[[#This Row],[APPAREMMENT]]/Tableau3[[#This Row],[Temps de parole total personnes ontologiques]]*600 -> 0.29779173 | S17: =Tableau3[[#This Row],[EVIDEMMENT]]/Tableau3[[#This Row],[Temps de parole total personnes ontologiques]]*600 -> 0.29779173 | T17: =Tableau3[[#This Row],[MANIFESTEMENT]]/Tableau3[[#This Row],[Temps de parole total personnes ontologiques]]*600 -> 0 | U17: =Tableau3[[#This Row],[VISIBLEMENT]]/Tableau3[[#This Row],[Temps de parole total personnes ontologiques]]*600 -> 0 | V17: =SUM(Tableau3[[#This Row],[avoir l''air '[look like'] per 10 min]:[visiblement '[visibly'] per 10 min]]) -> 1.7867504
A18: BUG | H18: 5 | K18: =SUM(B18:J18) -> 5 | L18: =_xlfn.XLOOKUP(Tableau3[[#This Row],[Personnes ontologiques]],'TEMPS PAROLE PERS_ONTO'!A:A,'TEMPS PAROLE PERS_ONTO'!B:B) -> 622.932 | M18: =Tableau3[[#This Row],[AVOIR L''AIR]]/Tableau3[[#This Row],[Temps de parole total personnes ontologiques]]*600 -> 0 | N18: =Tableau3[[#This Row],[AVOIR L''IMPRESSION]]/Tableau3[[#This Row],[Temps de parole total personnes ontologiques]]*600 -> 0 | O18: =Tableau3[[#This Row],[DONNER L''IMPRESSION]]/Tableau3[[#This Row],[Temps de parole total personnes ontologiques]]*600 -> 0 | P18: =Tableau3[[#This Row],[PARAITRE]]/Tableau3[[#This Row],[Temps de parole total personnes ontologiques]]*600 -> 0 | Q18: =Tableau3[[#This Row],[SEMBLER]]/Tableau3[[#This Row],[Temps de parole total personnes ontologiques]]*600 -> 0 | R18: =Tableau3[[#This Row],[APPAREMMENT]]/Tableau3[[#This Row],[Temps de parole total personnes ontologiques]]*600 -> 0 | S18: =Tableau3[[#This Row],[EVIDEMMENT]]/Tableau3[[#This Row],[Temps de parole total personnes ontologiques]]*600 -> 4.815935 | T18: =Tableau3[[#This Row],[MANIFESTEMENT]]/Tableau3[[#This Row],[Temps de parole total personnes ontologiques]]*600 -> 0 | U18: =Tableau3[[#This Row],[VISIBLEMENT]]/Tableau3[[#This Row],[Temps de parole total personnes ontologiques]]*600 -> 0 | V18: =SUM(Tableau3[[#This Row],[avoir l''air '[look like'] per 10 min]:[visiblement '[visibly'] per 10 min]]) -> 4.815935
A19: PEL | E19: 2 | F19: 1 | H19: 2 | K19: =SUM(B19:J19) -> 5 | L19: =_xlfn.XLOOKUP(Tableau3[[#This Row],[Personnes ontologiques]],'TEMPS PAROLE PERS_ONTO'!A:A,'TEMPS PAROLE PERS_ONTO'!B:B) -> 706.592 | M19: =Tableau3[[#This Row],[AVOIR L''AIR]]/Tableau3[[#This Row],[Temps de parole total personnes ontologiques]]*600 -> 0 | N19: =Tableau3[[#This Row],[AVOIR L''IMPRESSION]]/Tableau3[[#This Row],[Temps de parole total personnes ontologiques]]*600 -> 0 | O19: =Tableau3[[#This Row],[DONNER L''IMPRESSION]]/Tableau3[[#This Row],[Temps de parole total personnes ontologiques]]*600 -> 0 | P19: =Tableau3[[#This Row],[PARAITRE]]/Tableau3[[#This Row],[Temps de parole total personnes ontologiques]]*600 -> 1.6982926 | Q19: =Tableau3[[#This Row],[SEMBLER]]/Tableau3[[#This Row],[Temps de parole total personnes ontologiques]]*600 -> 0.84914632 | R19: =Tableau3[[#This Row],[APPAREMMENT]]/Tableau3[[#This Row],[Temps de parole total personnes ontologiques]]*600 -> 0 | S19: =Tableau3[[#This Row],[EVIDEMMENT]]/Tableau3[[#This Row],[Temps de parole total personnes ontologiques]]*600 -> 1.6982926 | T19: =Tableau3[[#This Row],[MANIFESTEMENT]]/Tableau3[[#This Row],[Temps de parole total personnes ontologiques]]*600 -> 0 | U19: =Tableau3[[#This Row],[VISIBLEMENT]]/Tableau3[[#This Row],[Temps de parole total personnes ontologiques]]*600 -> 0 | V19: =SUM(Tableau3[[#This Row],[avoir l''air '[look like'] per 10 min]:[visiblement '[visibly'] per 10 min]]) -> 4.2457316
A20: ALE | E20: 1 | H20: 4 | K20: =SUM(B20:J20) -> 5 | L20: =_xlfn.XLOOKUP(Tableau3[[#This Row],[Personnes ontologiques]],'TEMPS PAROLE PERS_ONTO'!A:A,'TEMPS PAROLE PERS_ONTO'!B:B) -> 962.482 | M20: =Tableau3[[#This Row],[AVOIR L''AIR]]/Tableau3[[#This Row],[Temps de parole total personnes ontologiques]]*600 -> 0 | N20: =Tableau3[[#This Row],[AVOIR L''IMPRESSION]]/Tableau3[[#This Row],[Temps de parole total personnes ontologiques]]*600 -> 0 | O20: =Tableau3[[#This Row],[DONNER L''IMPRESSION]]/Tableau3[[#This Row],[Temps de parole total personnes ontologiques]]*600 -> 0 | P20: =Tableau3[[#This Row],[PARAITRE]]/Tableau3[[#This Row],[Temps de parole total personnes ontologiques]]*600 -> 0.62338828 | Q20: =Tableau3[[#This Row],[SEMBLER]]/Tableau3[[#This Row],[Temps de parole total personnes ontologiques]]*600 -> 0 | R20: =Tableau3[[#This Row],[APPAREMMENT]]/Tableau3[[#This Row],[Temps de parole total personnes ontologiques]]*600 -> 0 | S20: =Tableau3[[#This Row],[EVIDEMMENT]]/Tableau3[[#This Row],[Temps de parole total personnes ontologiques]]*600 -> 2.4935531 | T20: =Tableau3[[#This Row],[MANIFESTEMENT]]/Tableau3[[#This Row],[Temps de parole total personnes ontologiques]]*600 -> 0 | U20: =Tableau3[[#This Row],[VISIBLEMENT]]/Tableau3[[#This Row],[Temps de parole total personnes ontologiques]]*600 -> 0 | V20: =SUM(Tableau3[[#This Row],[avoir l''air '[look like'] per 10 min]:[visiblement '[visibly'] per 10 min]]) -> 3.1169414
A21: DEL | F21: 2 | H21: 2 | I21: 1 | K21: =SUM(B21:J21) -> 5 | L21: =_xlfn.XLOOKUP(Tableau3[[#This Row],[Personnes ontologiques]],'TEMPS PAROLE PERS_ONTO'!A:A,'TEMPS PAROLE PERS_ONTO'!B:B) -> 1015.734 | M21: =Tableau3[[#This Row],[AVOIR L''AIR]]/Tableau3[[#This Row],[Temps de parole total personnes ontologiques]]*600 -> 0 | N21: =Tableau3[[#This Row],[AVOIR L''IMPRESSION]]/Tableau3[[#This Row],[Temps de parole total personnes ontologiques]]*600 -> 0 | O21: =Tableau3[[#This Row],[DONNER L''IMPRESSION]]/Tableau3[[#This Row],[Temps de parole total personnes ontologiques]]*600 -> 0 | P21: =Tableau3[[#This Row],[PARAITRE]]/Tableau3[[#This Row],[Temps de parole total personnes ontologiques]]*600 -> 0 | Q21: =Tableau3[[#This Row],[SEMBLER]]/Tableau3[[#This Row],[Temps de parole total personnes ontologiques]]*600 -> 1.1814117 | R21: =Tableau3[[#This Row],[APPAREMMENT]]/Tableau3[[#This Row],[Temps de parole total personnes ontologiques]]*600 -> 0 | S21: =Tableau3[[#This Row],[EVIDEMMENT]]/Tableau3[[#This Row],[Temps de parole total personnes ontologiques]]*600 -> 1.1814117 | T21: =Tableau3[[#This Row],[MANIFESTEMENT]]/Tableau3[[#This Row],[Temps de parole total personnes ontologiques]]*600 -> 0.59070583 | U21: =Tableau3[[#This Row],[VISIBLEMENT]]/Tableau3[[#This Row],[Temps de parole total personnes ontologiques]]*600 -> 0 | V21: =SUM(Tableau3[[#This Row],[avoir l''air '[look like'] per 10 min]:[visiblement '[visibly'] per 10 min]]) -> 2.9535292
A22: SAL | F22: 5 | K22: =SUM(B22:J22) -> 5 | L22: =_xlfn.XLOOKUP(Tableau3[[#This Row],[Personnes ontologiques]],'TEMPS PAROLE PERS_ONTO'!A:A,'TEMPS PAROLE PERS_ONTO'!B:B) -> 1503.862 | M22: =Tableau3[[#This Row],[AVOIR L''AIR]]/Tableau3[[#This Row],[Temps de parole total personnes ontologiques]]*600 -> 0 | N22: =Tableau3[[#This Row],[AVOIR L''IMPRESSION]]/Tableau3[[#This Row],[Temps de parole total personnes ontologiques]]*600 -> 0 | O22: =Tableau3[[#This Row],[DONNER L''IMPRESSION]]/Tableau3[[#This Row],[Temps de parole total personnes ontologiques]]*600 -> 0 | P22: =Tableau3[[#This Row],[PARAITRE]]/Tableau3[[#This Row],[Temps de parole total personnes ontologiques]]*600 -> 0 | Q22: =Tableau3[[#This Row],[SEMBLER]]/Tableau3[[#This Row],[Temps de parole total personnes ontologiques]]*600 -> 1.9948639 | R22: =Tableau3[[#This Row],[APPAREMMENT]]/Tableau3[[#This Row],[Temps de parole total personnes ontologiques]]*600 -> 0 | S22: =Tableau3[[#This Row],[EVIDEMMENT]]/Tableau3[[#This Row],[Temps de parole total personnes ontologiques]]*600 -> 0 | T22: =Tableau3[[#This Row],[MANIFESTEMENT]]/Tableau3[[#This Row],[Temps de parole total personnes ontologiques]]*600 -> 0 | U22: =Tableau3[[#This Row],[VISIBLEMENT]]/Tableau3[[#This Row],[Temps de parole total personnes ontologiques]]*600 -> 0 | V22: =SUM(Tableau3[[#This Row],[avoir l''air '[look like'] per 10 min]:[visiblement '[visibly'] per 10 min]]) -> 1.9948639
A23: MIC | C23: 2 | F23: 3 | K23: =SUM(B23:J23) -> 5 | L23: =_xlfn.XLOOKUP(Tableau3[[#This Row],[Personnes ontologiques]],'TEMPS PAROLE PERS_ONTO'!A:A,'TEMPS PAROLE PERS_ONTO'!B:B) -> 4526.901 | M23: =Tableau3[[#This Row],[AVOIR L''AIR]]/Tableau3[[#This Row],[Temps de parole total personnes ontologiques]]*600 -> 0 | N23: =Tableau3[[#This Row],[AVOIR L''IMPRESSION]]/Tableau3[[#This Row],[Temps de parole total personnes ontologiques]]*600 -> 0.26508201 | O23: =Tableau3[[#This Row],[DONNER L''IMPRESSION]]/Tableau3[[#This Row],[Temps de parole total personnes ontologiques]]*600 -> 0 | P23: =Tableau3[[#This Row],[PARAITRE]]/Tableau3[[#This Row],[Temps de parole total personnes ontologiques]]*600 -> 0 | Q23: =Tableau3[[#This Row],[SEMBLER]]/Tableau3[[#This Row],[Temps de parole total personnes ontologiques]]*600 -> 0.39762301 | R23: =Tableau3[[#This Row],[APPAREMMENT]]/Tableau3[[#This Row],[Temps de parole total personnes ontologiques]]*600 -> 0 | S23: =Tableau3[[#This Row],[EVIDEMMENT]]/Tableau3[[#This Row],[Temps de parole total personnes ontologiques]]*600 -> 0 | T23: =Tableau3[[#This Row],[MANIFESTEMENT]]/Tableau3[[#This Row],[Temps de parole total personnes ontologiques]]*600 -> 0 | U23: =Tableau3[[#This Row],[VISIBLEMENT]]/Tableau3[[#This Row],[Temps de parole total personnes ontologiques]]*600 -> 0 | V23: =SUM(Tableau3[[#This Row],[avoir l''air '[look like'] per 10 min]:[visiblement '[visibly'] per 10 min]]) -> 0.66270502
A24: LAT | F24: 1 | H24: 3 | K24: =SUM(B24:J24) -> 4 | L24: =_xlfn.XLOOKUP(Tableau3[[#This Row],[Personnes ontologiques]],'TEMPS PAROLE PERS_ONTO'!A:A,'TEMPS PAROLE PERS_ONTO'!B:B) -> 250.108 | M24: =Tableau3[[#This Row],[AVOIR L''AIR]]/Tableau3[[#This Row],[Temps de parole total personnes ontologiques]]*600 -> 0 | N24: =Tableau3[[#This Row],[AVOIR L''IMPRESSION]]/Tableau3[[#This Row],[Temps de parole total personnes ontologiques]]*600 -> 0 | O24: =Tableau3[[#This Row],[DONNER L''IMPRESSION]]/Tableau3[[#This Row],[Temps de parole total personnes ontologiques]]*600 -> 0 | P24: =Tableau3[[#This Row],[PARAITRE]]/Tableau3[[#This Row],[Temps de parole total personnes ontologiques]]*600 -> 0 | Q24: =Tableau3[[#This Row],[SEMBLER]]/Tableau3[[#This Row],[Temps de parole total personnes ontologiques]]*600 -> 2.3989636 | R24: =Tableau3[[#This Row],[APPAREMMENT]]/Tableau3[[#This Row],[Temps de parole total personnes ontologiques]]*600 -> 0 | S24: =Tableau3[[#This Row],[EVIDEMMENT]]/Tableau3[[#This Row],[Temps de parole total personnes ontologiques]]*600 -> 7.1968909 | T24: =Tableau3[[#This Row],[MANIFESTEMENT]]/Tableau3[[#This Row],[Temps de parole total personnes ontologiques]]*600 -> 0 | U24: =Tableau3[[#This Row],[VISIBLEMENT]]/Tableau3[[#This Row],[Temps de parole total personnes ontologiques]]*600 -> 0 | V24: =SUM(Tableau3[[#This Row],[avoir l''air '[look like'] per 10 min]:[visiblement '[visibly'] per 10 min]]) -> 9.5958546
A25: FRI | C25: 1 | F25: 2 | G25: 1 | K25: =SUM(B25:J25) -> 4 | L25: =_xlfn.XLOOKUP(Tableau3[[#This Row],[Personnes ontologiques]],'TEMPS PAROLE PERS_ONTO'!A:A,'TEMPS PAROLE PERS_ONTO'!B:B) -> 359.832 | M25: =Tableau3[[#This Row],[AVOIR L''AIR]]/Tableau3[[#This Row],[Temps de parole total personnes ontologiques]]*600 -> 0 | N25: =Tableau3[[#This Row],[AVOIR L''IMPRESSION]]/Tableau3[[#This Row],[Temps de parole total personnes ontologiques]]*600 -> 1.6674448 | O25: =Tableau3[[#This Row],[DONNER L''IMPRESSION]]/Tableau3[[#This Row],[Temps de parole total personnes ontologiques]]*600 -> 0 | P25: =Tableau3[[#This Row],[PARAITRE]]/Tableau3[[#This Row],[Temps de parole total personnes ontologiques]]*600 -> 0 | Q25: =Tableau3[[#This Row],[SEMBLER]]/Tableau3[[#This Row],[Temps de parole total personnes ontologiques]]*600 -> 3.3348896 | R25: =Tableau3[[#This Row],[APPAREMMENT]]/Tableau3[[#This Row],[Temps de parole total personnes ontologiques]]*600 -> 1.6674448 | S25: =Tableau3[[#This Row],[EVIDEMMENT]]/Tableau3[[#This Row],[Temps de parole total personnes ontologiques]]*600 -> 0 | T25: =Tableau3[[#This Row],[MANIFESTEMENT]]/Tableau3[[#This Row],[Temps de parole total personnes ontologiques]]*600 -> 0 | U25: =Tableau3[[#This Row],[VISIBLEMENT]]/Tableau3[[#This Row],[Temps de parole total personnes ontologiques]]*600 -> 0 | V25: =SUM(Tableau3[[#This Row],[avoir l''air '[look like'] per 10 min]:[visiblement '[visibly'] per 10 min]]) -> 6.6697792
A26: ANT | H26: 4 | K26: =SUM(B26:J26) -> 4 | L26: =_xlfn.XLOOKUP(Tableau3[[#This Row],[Personnes ontologiques]],'TEMPS PAROLE PERS_ONTO'!A:A,'TEMPS PAROLE PERS_ONTO'!B:B) -> 464.117 | M26: =Tableau3[[#This Row],[AVOIR L''AIR]]/Tableau3[[#This Row],[Temps de parole total personnes ontologiques]]*600 -> 0 | N26: =Tableau3[[#This Row],[AVOIR L''IMPRESSION]]/Tableau3[[#This Row],[Temps de parole total personnes ontologiques]]*600 -> 0 | O26: =Tableau3[[#This Row],[DONNER L''IMPRESSION]]/Tableau3[[#This Row],[Temps de parole total personnes ontologiques]]*600 -> 0 | P26: =Tableau3[[#This Row],[PARAITRE]]/Tableau3[[#This Row],[Temps de parole total personnes ontologiques]]*600 -> 0 | Q26: =Tableau3[[#This Row],[SEMBLER]]/Tableau3[[#This Row],[Temps de parole total personnes ontologiques]]*600 -> 0 | R26: =Tableau3[[#This Row],[APPAREMMENT]]/Tableau3[[#This Row],[Temps de parole total personnes ontologiques]]*600 -> 0 | S26: =Tableau3[[#This Row],[EVIDEMMENT]]/Tableau3[[#This Row],[Temps de parole total personnes ontologiques]]*600 -> 5.1711099 | T26: =Tableau3[[#This Row],[MANIFESTEMENT]]/Tableau3[[#This Row],[Temps de parole total personnes ontologiques]]*600 -> 0 | U26: =Tableau3[[#This Row],[VISIBLEMENT]]/Tableau3[[#This Row],[Temps de parole total personnes ontologiques]]*600 -> 0 | V26: =SUM(Tableau3[[#This Row],[avoir l''air '[look like'] per 10 min]:[visiblement '[visibly'] per 10 min]]) -> 5.1711099
A27: P32 | H27: 4 | K27: =SUM(B27:J27) -> 4 | L27: =_xlfn.XLOOKUP(Tableau3[[#This Row],[Personnes ontologiques]],'TEMPS PAROLE PERS_ONTO'!A:A,'TEMPS PAROLE PERS_ONTO'!B:B) -> 485.637 | M27: =Tableau3[[#This Row],[AVOIR L''AIR]]/Tableau3[[#This Row],[Temps de parole total personnes ontologiques]]*600 -> 0 | N27: =Tableau3[[#This Row],[AVOIR L''IMPRESSION]]/Tableau3[[#This Row],[Temps de parole total personnes ontologiques]]*600 -> 0 | O27: =Tableau3[[#This Row],[DONNER L''IMPRESSION]]/Tableau3[[#This Row],[Temps de parole total personnes ontologiques]]*600 -> 0 | P27: =Tableau3[[#This Row],[PARAITRE]]/Tableau3[[#This Row],[Temps de parole total personnes ontologiques]]*600 -> 0 | Q27: =Tableau3[[#This Row],[SEMBLER]]/Tableau3[[#This Row],[Temps de parole total personnes ontologiques]]*600 -> 0 | R27: =Tableau3[[#This Row],[APPAREMMENT]]/Tableau3[[#This Row],[Temps de parole total personnes ontologiques]]*600 -> 0 | S27: =Tableau3[[#This Row],[EVIDEMMENT]]/Tableau3[[#This Row],[Temps de parole total personnes ontologiques]]*600 -> 4.9419628 | T27: =Tableau3[[#This Row],[MANIFESTEMENT]]/Tableau3[[#This Row],[Temps de parole total personnes ontologiques]]*600 -> 0 | U27: =Tableau3[[#This Row],[VISIBLEMENT]]/Tableau3[[#This Row],[Temps de parole total personnes ontologiques]]*600 -> 0 | V27: =SUM(Tableau3[[#This Row],[avoir l''air '[look like'] per 10 min]:[visiblement '[visibly'] per 10 min]]) -> 4.9419628
A28: BEN | F28: 3 | H28: 1 | K28: =SUM(B28:J28) -> 4 | L28: =_xlfn.XLOOKUP(Tableau3[[#This Row],[Personnes ontologiques]],'TEMPS PAROLE PERS_ONTO'!A:A,'TEMPS PAROLE PERS_ONTO'!B:B) -> 661.135 | M28: =Tableau3[[#This Row],[AVOIR L''AIR]]/Tableau3[[#This Row],[Temps de parole total personnes ontologiques]]*600 -> 0 | N28: =Tableau3[[#This Row],[AVOIR L''IMPRESSION]]/Tableau3[[#This Row],[Temps de parole total personnes ontologiques]]*600 -> 0 | O28: =Tableau3[[#This Row],[DONNER L''IMPRESSION]]/Tableau3[[#This Row],[Temps de parole total personnes ontologiques]]*600 -> 0 | P28: =Tableau3[[#This Row],[PARAITRE]]/Tableau3[[#This Row],[Temps de parole total personnes ontologiques]]*600 -> 0 | Q28: =Tableau3[[#This Row],[SEMBLER]]/Tableau3[[#This Row],[Temps de parole total personnes ontologiques]]*600 -> 2.7225907 | R28: =Tableau3[[#This Row],[APPAREMMENT]]/Tableau3[[#This Row],[Temps de parole total personnes ontologiques]]*600 -> 0 | S28: =Tableau3[[#This Row],[EVIDEMMENT]]/Tableau3[[#This Row],[Temps de parole total personnes ontologiques]]*600 -> 0.90753023 | T28: =Tableau3[[#This Row],[MANIFESTEMENT]]/Tableau3[[#This Row],[Temps de parole total personnes ontologiques]]*600 -> 0 | U28: =Tableau3[[#This Row],[VISIBLEMENT]]/Tableau3[[#This Row],[Temps de parole total personnes ontologiques]]*600 -> 0 | V28: =SUM(Tableau3[[#This Row],[avoir l''air '[look like'] per 10 min]:[visiblement '[visibly'] per 10 min]]) -> 3.6301209
A29: MAI | F29: 1 | H29: 1 | I29: 2 | K29: =SUM(B29:J29) -> 4 | L29: =_xlfn.XLOOKUP(Tableau3[[#This Row],[Personnes ontologiques]],'TEMPS PAROLE PERS_ONTO'!A:A,'TEMPS PAROLE PERS_ONTO'!B:B) -> 753.907 | M29: =Tableau3[[#This Row],[AVOIR L''AIR]]/Tableau3[[#This Row],[Temps de parole total personnes ontologiques]]*600 -> 0 | N29: =Tableau3[[#This Row],[AVOIR L''IMPRESSION]]/Tableau3[[#This Row],[Temps de parole total personnes ontologiques]]*600 -> 0 | O29: =Tableau3[[#This Row],[DONNER L''IMPRESSION]]/Tableau3[[#This Row],[Temps de parole total personnes ontologiques]]*600 -> 0 | P29: =Tableau3[[#This Row],[PARAITRE]]/Tableau3[[#This Row],[Temps de parole total personnes ontologiques]]*600 -> 0 | Q29: =Tableau3[[#This Row],[SEMBLER]]/Tableau3[[#This Row],[Temps de parole total personnes ontologiques]]*600 -> 0.79585413 | R29: =Tableau3[[#This Row],[APPAREMMENT]]/Tableau3[[#This Row],[Temps de parole total personnes ontologiques]]*600 -> 0 | S29: =Tableau3[[#This Row],[EVIDEMMENT]]/Tableau3[[#This Row],[Temps de parole total personnes ontologiques]]*600 -> 0.79585413 | T29: =Tableau3[[#This Row],[MANIFESTEMENT]]/Tableau3[[#This Row],[Temps de parole total personnes ontologiques]]*600 -> 1.5917083 | U29: =Tableau3[[#This Row],[VISIBLEMENT]]/Tableau3[[#This Row],[Temps de parole total personnes ontologiques]]*600 -> 0 | V29: =SUM(Tableau3[[#This Row],[avoir l''air '[look like'] per 10 min]:[visiblement '[visibly'] per 10 min]]) -> 3.1834165
A30: RSI | H30: 4 | K30: =SUM(B30:J30) -> 4 | L30: =_xlfn.XLOOKUP(Tableau3[[#This Row],[Personnes ontologiques]],'TEMPS PAROLE PERS_ONTO'!A:A,'TEMPS PAROLE PERS_ONTO'!B:B) -> 764.229 | M30: =Tableau3[[#This Row],[AVOIR L''AIR]]/Tableau3[[#This Row],[Temps de parole total personnes ontologiques]]*600 -> 0 | N30: =Tableau3[[#This Row],[AVOIR L''IMPRESSION]]/Tableau3[[#This Row],[Temps de parole total personnes ontologiques]]*600 -> 0 | O30: =Tableau3[[#This Row],[DONNER L''IMPRESSION]]/Tableau3[[#This Row],[Temps de parole total personnes ontologiques]]*600 -> 0 | P30: =Tableau3[[#This Row],[PARAITRE]]/Tableau3[[#This Row],[Temps de parole total personnes ontologiques]]*600 -> 0 | Q30: =Tableau3[[#This Row],[SEMBLER]]/Tableau3[[#This Row],[Temps de parole total personnes ontologiques]]*600 -> 0 | R30: =Tableau3[[#This Row],[APPAREMMENT]]/Tableau3[[#This Row],[Temps de parole total personnes ontologiques]]*600 -> 0 | S30: =Tableau3[[#This Row],[EVIDEMMENT]]/Tableau3[[#This Row],[Temps de parole total personnes ontologiques]]*600 -> 3.14042 | T30: =Tableau3[[#This Row],[MANIFESTEMENT]]/Tableau3[[#This Row],[Temps de parole total personnes ontologiques]]*600 -> 0 | U30: =Tableau3[[#This Row],[VISIBLEMENT]]/Tableau3[[#This Row],[Temps de parole total personnes ontologiques]]*600 -> 0 | V30: =SUM(Tableau3[[#This Row],[avoir l''air '[look like'] per 10 min]:[visiblement '[visibly'] per 10 min]]) -> 3.14042
A31: SEB | F31: 2 | G31: 1 | H31: 1 | K31: =SUM(B31:J31) -> 4 | L31: =_xlfn.XLOOKUP(Tableau3[[#This Row],[Personnes ontologiques]],'TEMPS PAROLE PERS_ONTO'!A:A,'TEMPS PAROLE PERS_ONTO'!B:B) -> 1187.326 | M31: =Tableau3[[#This Row],[AVOIR L''AIR]]/Tableau3[[#This Row],[Temps de parole total personnes ontologiques]]*600 -> 0 | N31: =Tableau3[[#This Row],[AVOIR L''IMPRESSION]]/Tableau3[[#This Row],[Temps de parole total personnes ontologiques]]*600 -> 0 | O31: =Tableau3[[#This Row],[DONNER L''IMPRESSION]]/Tableau3[[#This Row],[Temps de parole total personnes ontologiques]]*600 -> 0 | P31: =Tableau3[[#This Row],[PARAITRE]]/Tableau3[[#This Row],[Temps de parole total personnes ontologiques]]*600 -> 0 | Q31: =Tableau3[[#This Row],[SEMBLER]]/Tableau3[[#This Row],[Temps de parole total personnes ontologiques]]*600 -> 1.0106744 | R31: =Tableau3[[#This Row],[APPAREMMENT]]/Tableau3[[#This Row],[Temps de parole total personnes ontologiques]]*600 -> 0.5053372 | S31: =Tableau3[[#This Row],[EVIDEMMENT]]/Tableau3[[#This Row],[Temps de parole total personnes ontologiques]]*600 -> 0.5053372 | T31: =Tableau3[[#This Row],[MANIFESTEMENT]]/Tableau3[[#This Row],[Temps de parole total personnes ontologiques]]*600 -> 0 | U31: =Tableau3[[#This Row],[VISIBLEMENT]]/Tableau3[[#This Row],[Temps de parole total personnes ontologiques]]*600 -> 0 | V31: =SUM(Tableau3[[#This Row],[avoir l''air '[look like'] per 10 min]:[visiblement '[visibly'] per 10 min]]) -> 2.0213488
